<?xml version="1.0" ?>
<robot name="base_world" xmlns:xacro="http://www.ros.org/wiki/xacro">
  <link name="world_frame_link"/>
  <joint name="base_joint_fixed" type="fixed">
    <origin rpy="0 0 0" xyz="1 1 0"/>
    <parent link="world_frame_link"/>
    <child link="base_frame_link"/>
  </joint>
  <link name="base_frame_link"/>
  <joint name="laser_joint_fixed" type="fixed">
    <axis xyz="0 1 0"/>
    <origin rpy="0 0 0" xyz="0 0 1"/>
    <parent link="world_frame_link"/>
    <child link="laser_frame_link"/>
  </joint>
  <link name="laser_frame_link"/>
  <joint name="dynamic_joint_conti" type="continuous">
    <parent link="base_frame_link"/>
    <child link="dynamic_joint_frame_link"/>
    <origin rpy="0 0 0" xyz="0.5 0.5 0.5"/>
    <axis xyz="0 0 1"/>
    <dynamics damping="0.7"/>
  </joint>
  <link name="dynamic_joint_frame_link"/>
  <joint name="extension_joint_fixed" type="fixed">
    <origin rpy="0 0 0" xyz="1 1 1"/>
    <parent link="dynamic_joint_frame_link"/>
    <child link="extension_joint_frame_link"/>
  </joint>
  <link name="extension_joint_frame_link"/>
</robot>
